#define CATCH_CONFIG_MAIN
#include <catch2/catch_test_macros.hpp>
#include <stdexcept>
#include <iostream>

void test(int n)
{
    if (n == 42) {
        return;
    }
    throw std::runtime_error(
        "Not the answer");
}

TEST_CASE("My first test", "[my]")
{
    INFO("Testing");
    CHECK(1 + 1 == 2);
    CHECK_THROWS_AS(
        test(41), std::runtime_error);
    CHECK_NOTHROW(test(42));

    int expected = 5;
    CHECK(2 + 2 == expected);
}

TEST_CASE("test", "[test]")
{
    CHECK(1 == 1);
    CHECK(1 == 2);
}
